## 11.1 常见异常

1：AttributeError异常  
试图访问一个类中不存在的成员（包括：成员变量、属性和成员方法）。  

例如，创建一个类，访问类中没有的方法或属性：

    >>> class Animal(object):
	pass

    >>> a1 = Animal()
    >>> a1.run()
    Traceback (most recent call last):
      File "<pyshell#4>", line 1, in <module>
        a1.run()
    AttributeError: 'Animal' object has no attribute 'run'
    >>> a1.age
    Traceback (most recent call last):
      File "<pyshell#5>", line 1, in <module>
        a1.age
    AttributeError: 'Animal' object has no attribute 'age'

2：OSError异常  
操作系统相关异常，Python 3.3版本后IOError（输入输出异常）也并入到OSError异常，所以输入输出异常也属于OSError异常，例如“未找到文件”或“磁盘已满”异常。

例如：  

    >>> f = open('abc.txt')
    Traceback (most recent call last):
      File "<pyshell#8>", line 1, in <module>
        f = open('abc.txt')
    FileNotFoundError: [Errno 2] No such file or directory: 'abc.txt'

其中“FileNotFoundError”属于“OSError”异常的子类。

3：IndexError异常  
在访问序列元素时，下标索引超出取值范围所引发的异常。

例如：  

    >>> code_list = [125,56,48,59]
    >>> code_list[4]
    Traceback (most recent call last):
      File "<pyshell#12>", line 1, in <module>
        code_list[4]
    IndexError: list index out of range

在创建的序列中，一共有四个元素，其中最大的元素的索引是“3”，当我们访问索引是“4”的元素时，出现下表越界异常。

4：KeyError异常  
试图访问字典里不存在的键时而引发的异常。

例如：

    >>> dict1 = {105:'tony'}
    >>> dict1[104]
    Traceback (most recent call last):
      File "<pyshell#17>", line 1, in <module>
        dict1[104]
    KeyError: 104

一个字典的key值为“105”，当访问key值为“104”时，由于字典中不存在这样的键值，所以会报出异常。

5：NameError异常  
试图使用一个不存在的变量而引发的异常。

例如：

    >>> value1
    Traceback (most recent call last):
      File "<pyshell#21>", line 1, in <module>
        value1
    NameError: name 'value1' is not defined

原来有个变量叫“value”，结果写成“value1”，因为没有这样的变量，结果导致报出该异常。

6：TypeError异常  
试图传入变量类型与要求的不符合时而引发的异常。

例如：

    >>> i = input('请输入数字：')
    请输入数字：10
    >>> print(5/i)
    Traceback (most recent call last):
      File "<pyshell#27>", line 1, in <module>
        print(5/i)
    TypeError: unsupported operand type(s) for /: 'int' and 'str'

首先我们从键盘输入一个数字“10”，可实际上接收的是一个字符串类型数据，当紧接着进行除法运算时，则报出该异常。

7：ValueError异常  
由于传入一个无效的参数值而引发的。

例如：

    >>> i = input('请输入数字：')
    请输入数字：qwe
    >>> print(5/int(i))
    Traceback (most recent call last):
      File "<pyshell#35>", line 1, in <module>
        print(5/int(i))
    ValueError: invalid literal for int() with base 10: 'qwe'

传入的参数是一些字符“qwe”，将这些字符串转换为整数类型时报出异常。

